<?xml version="1.0"?>

<robot xmlns:xacro="http://www.ros.org/wiki/xacro" name="rover_model">

    <link name="base_link">
        <visual>
            <geometry>
                <box size="0.7 1.4 0.4"/>
            </geometry>
            <origin rpy="0 0 0" xyz="0 0 0.2"/>
            <material name="Brown">
                <color rgba="${112/255} ${51/255} ${10/255} 1.0"/>
            </material>
        </visual>
        <collision>
            <geometry>
                <box size="0.7 1.4 0.4"/>
            </geometry>
            <origin rpy="0 0 0" xyz="0 0 0.2"/>
            <material name="Brown">
                <color rgba="${112/255} ${51/255} ${10/255} 1.0"/>
            </material>
        </collision>
        <inertial>
            <mass value="30" />
            <inertia ixx="1.0" ixy="0.0" ixz="0.0" iyy="1.0" iyz="0.0" izz="1.0" />
        </inertial>
    </link>

    <link name="left_rocker">
        <visual>
            <geometry>
                <box size="0.2 1.4 0.2"/>
            </geometry>
            <origin rpy="0 0 0" xyz="0.1 0 0.1"/>
            <material name="Grey">
                <color rgba="${203/255} ${200/255} ${191/255} 1.0"/>
            </material>
        </visual>
        <collision>
            <geometry>
                <box size="0.2 1.4 0.2"/>
            </geometry>
            <origin rpy="0 0 0" xyz="0.1 0 0.1"/>
            <material name="Grey">
                <color rgba="${203/255} ${200/255} ${191/255} 1.0"/>
            </material>
        </collision>
        <inertial>
            <mass value="1" />
            <inertia ixx="1.0" ixy="0.0" ixz="0.0" iyy="1.0" iyz="0.0" izz="1.0" />
        </inertial>
    </link>

    <link name="right_rocker">
        <visual>
            <geometry>
                <box size="0.2 1.4 0.2"/>
                <box size="0.2 1.4 0.2"/>
                <box size="0.2 1.4 0.2"/>
            </geometry>
            <origin rpy="0 0 0" xyz="-0.1 0 0.1"/>
            <material name="Grey">
                <color rgba="${203/255} ${200/255} ${191/255} 1.0"/>
            </material>
        </visual>
        <collision>
            <geometry>
                <box size="0.2 1.4 0.2"/>
                <box size="0.2 1.4 0.2"/>
                <box size="0.2 1.4 0.2"/>
            </geometry>
            <origin rpy="0 0 0" xyz="-0.1 0 0.1"/>
            <material name="Grey">
                <color rgba="${203/255} ${200/255} ${191/255} 1.0"/>
            </material>
        </collision>
        <inertial>
            <mass value="1" />
            <inertia ixx="1.0" ixy="0.0" ixz="0.0" iyy="1.0" iyz="0.0" izz="1.0" />
        </inertial>
    </link>

    <link name="wheel_front_left">
        <visual>
            <geometry>
                <cylinder radius="0.15" length="0.2"/>
            </geometry>
            <origin rpy="0 1.570796 0" xyz="0.1 0 0"/>
            <material name="black">
                <color rgba="${12/255} ${12/255} ${12/255} 1.0"/>
            </material>
        </visual>
        <collision>
            <geometry>
                <cylinder radius="0.15" length="0.2"/>
            </geometry>
            <origin rpy="0 1.570796 0" xyz="0.1 0 0"/>
            <material name="black">
                <color rgba="${12/255} ${12/255} ${12/255} 1.0"/>
            </material>
        </collision>
        <inertial>
            <mass value="1" />
            <inertia ixx="1.0" ixy="0.0" ixz="0.0" iyy="1.0" iyz="0.0" izz="1.0" />
        </inertial>
    </link>

    <link name="wheel_front_right">
        <visual>
            <geometry>
                <cylinder radius="0.15" length="0.2"/>
            </geometry>
            <origin rpy="0 1.570796 0" xyz="-0.1 0 0"/>
            <material name="black">
                <color rgba="${12/255} ${12/255} ${12/255} 1.0"/>
            </material>
        </visual>
        <collision>
            <geometry>
                <cylinder radius="0.15" length="0.2"/>
            </geometry>
            <origin rpy="0 1.570796 0" xyz="-0.1 0 0"/>
            <material name="black">
                <color rgba="${12/255} ${12/255} ${12/255} 1.0"/>
            </material>
        </collision>
        <inertial>
            <mass value="1" />
            <inertia ixx="1.0" ixy="0.0" ixz="0.0" iyy="1.0" iyz="0.0" izz="1.0" />
        </inertial>
    </link>

    <link name="wheel_back_left">
        <visual>
            <geometry>
                <cylinder radius="0.15" length="0.2"/>
            </geometry>
            <origin rpy="0 1.570796 0" xyz="0.1 0 0"/>
            <material name="black">
                <color rgba="${12/255} ${12/255} ${12/255} 1.0"/>
            </material>
        </visual>
        <collision>
            <geometry>
                <cylinder radius="0.15" length="0.2"/>
            </geometry>
            <origin rpy="0 1.570796 0" xyz="0.1 0 0"/>
            <material name="black">
                <color rgba="${12/255} ${12/255} ${12/255} 1.0"/>
            </material>
        </collision>
        <inertial>
            <mass value="1" />
            <inertia ixx="1.0" ixy="0.0" ixz="0.0" iyy="1.0" iyz="0.0" izz="1.0" />
        </inertial>
    </link>

    <link name="wheel_back_right">
        <visual>
            <geometry>
                <cylinder radius="0.15" length="0.2"/>
            </geometry>
            <origin rpy="0 1.570796 0" xyz="-0.1 0 0"/>
            <material name="black">
                <color rgba="${12/255} ${12/255} ${12/255} 1.0"/>
            </material>
        </visual>
        <collision>
            <geometry>
                <cylinder radius="0.15" length="0.2"/>
            </geometry>
            <origin rpy="0 1.570796 0" xyz="-0.1 0 0"/>
            <material name="black">
                <color rgba="${12/255} ${12/255} ${12/255} 1.0"/>
            </material>
        </collision>
        <inertial>
            <mass value="1" />
            <inertia ixx="1.0" ixy="0.0" ixz="0.0" iyy="1.0" iyz="0.0" izz="1.0" />
        </inertial>
    </link>

    <link name="arm_link">
        <visual>
            <geometry>
                <box size="0.1 0.1 1.0"/>
            </geometry>
            <origin rpy="0 0 0" xyz="0 0 0.3"/>
            <material name="Green">
                <color rgba="${111/255} ${155/255} ${137/255} 1.0"/>
            </material>
        </visual>
        <inertial>
            <mass value="0.1" />
            <inertia ixx="1.0" ixy="0.0" ixz="0.0" iyy="1.0" iyz="0.0" izz="1.0" />
        </inertial>
    </link>

<<<<<<< HEAD
=======
    <link name="arm_connector">
        <visual>
            <geometry>
                <cylinder radius="0.05" length="0.1"/>
            </geometry>
            <origin rpy="0 1.570796 0" xyz="0 0 0.05"/>
            <material name="white">
            </material>
        </visual>
        <inertial>
            <mass value="0.1" />
            <inertia ixx="1.0" ixy="0.0" ixz="0.0" iyy="1.0" iyz="0.0" izz="1.0" />
        </inertial>
    </link>
>>>>>>> 056fd1fc542b84a082a617a9aa1b547c30798cec

    <link name="arm2_link2">
        <visual>
            <geometry>
                <cylinder radius="0.05" length="0.7"/>
            </geometry>
<<<<<<< HEAD
            <origin rpy="-1.3 0 0" xyz="0 -0.3 -0.05"/>
             <material name="Green">
             <color rgba="${111/255} ${155/255} ${137/255} 1.0"/>
        </material>
=======
            <origin rpy="1.3 0 0" xyz="0 0 -0.03"/>
            <material name="Green">
                <color rgba="${111/255} ${155/255} ${137/255} 1.0"/>
            </material>
>>>>>>> 056fd1fc542b84a082a617a9aa1b547c30798cec
        </visual>
        <inertial>
            <mass value="0.1" />
            <inertia ixx="1.0" ixy="0.0" ixz="0.0" iyy="1.0" iyz="0.0" izz="1.0" />
        </inertial>
    </link>

<<<<<<< HEAD
=======
    <link name="arm2_connector2">
        <visual>
            <geometry>
                <cylinder radius="0.05" length="0.1"/>
            </geometry>
            <origin rpy="0 1.570796 0" xyz="0 0 0"/>
            <material name="white">
            </material>
        </visual>
        <inertial>
            <mass value="0.1" />
            <inertia ixx="1.0" ixy="0.0" ixz="0.0" iyy="1.0" iyz="0.0" izz="1.0" />
        </inertial>
    </link>
>>>>>>> 056fd1fc542b84a082a617a9aa1b547c30798cec

    <link name="arm3_link3">
        <visual>
            <geometry>
                <cylinder radius="0.05" length="0.4"/>
            </geometry>
<<<<<<< HEAD
            <origin rpy="-0.5 0 0" xyz="0 -0.1 -0.15"/>
             <material name="Green">
             <color rgba="${111/255} ${155/255} ${137/255} 1.0"/>
        </material>
=======
            <origin rpy="0.5 0 0" xyz="0 0 0"/>
            <material name="Green">
                <color rgba="${111/255} ${155/255} ${137/255} 1.0"/>
            </material>
>>>>>>> 056fd1fc542b84a082a617a9aa1b547c30798cec
        </visual>
        <inertial>
            <mass value="0.1" />
            <inertia ixx="1.0" ixy="0.0" ixz="0.0" iyy="1.0" iyz="0.0" izz="1.0" />
        </inertial>
    </link>

    <link name="grip_connector">
        <visual>
            <geometry>
                <cylinder radius="0.05" length="0.25"/>
            </geometry>
            <origin rpy="0 1.570796 0" xyz="0 0 0"/>
            <material name="Purple">
                <color rgba="${78/255} ${88/255} ${188/255} 1.0"/>
            </material>
        </visual>
        <inertial>
            <mass value="0.1" />
            <inertia ixx="1.0" ixy="0.0" ixz="0.0" iyy="1.0" iyz="0.0" izz="1.0" />
        </inertial>
    </link>

    <link name="left_grip">
        <visual>
            <geometry>
                <cylinder radius="0.03" length="0.25"/>
            </geometry>
            <origin rpy="0 0.2 0" xyz="0 0 0"/>
            <material name="black">
                <color rgba="${12/255} ${12/255} ${12/255} 1.0"/>
            </material>
        </visual>
        <inertial>
            <mass value="0.1" />
            <inertia ixx="1.0" ixy="0.0" ixz="0.0" iyy="1.0" iyz="0.0" izz="1.0" />
        </inertial>
    </link>

    <link name="right_grip">
        <visual>
            <geometry>
                <cylinder radius="0.03" length="0.25"/>
            </geometry>
            <origin rpy="0 -0.2 0" xyz="0 0 0"/>
            <material name="black">
                <color rgba="${12/255} ${12/255} ${12/255} 1.0"/>
            </material>
        </visual>
        <inertial>
            <mass value="0.1" />
            <inertia ixx="1.0" ixy="0.0" ixz="0.0" iyy="1.0" iyz="0.0" izz="1.0" />
        </inertial>
    </link>




    <joint name="left_rocker_joint" type="revolute">
        <origin xyz="0.35 0.0 0.0" rpy="0.0 0.0 0.0"/>
        <parent link="base_link"/>
        <child link="left_rocker"/>
        <axis xyz="1 0 0"/>
        <limit lower="-0.5235988" upper="0.5235988" effort="0.0" velocity="0.0"/>
    </joint>

    <joint name="right_rocker_joint" type="revolute">
        <origin xyz="-0.35 0.0 0.0" rpy="0.0 0.0 0.0"/>
        <parent link="base_link"/>
        <child link="right_rocker"/>
        <axis xyz="1 0 0"/>
        <limit lower="-0.5235988" upper="0.5235988" effort="0" velocity="0"/>
    </joint>

    <joint name="wheel_front_left_joint" type="continuous">
        <origin xyz="0.2 -0.7 0.0" rpy="0.0 0.0 0.0"/>
        <parent link="left_rocker"/>
        <child link="wheel_front_left"/>
        <axis xyz="1 0 0"/>
        <limit effort="0" velocity="0"/>
    </joint>

    <joint name="wheel_front_right_joint" type="continuous">
        <origin xyz="-0.2 -0.7 0.0" rpy="0.0 0.0 0.0"/>
        <parent link="right_rocker"/>
        <child link="wheel_front_right"/>
        <axis xyz="1 0 0"/>
        <limit effort="0" velocity="0"/>
    </joint>

    <joint name="wheel_back_left_joint" type="continuous">
        <origin xyz="0.2 0.7 0.0" rpy="0.0 0.0 0.0"/>
        <parent link="left_rocker"/>
        <child link="wheel_back_left"/>
        <axis xyz="1 0 0"/>
        <limit effort="0" velocity="0"/>
    </joint>

    <joint name="wheel_back_right_joint" type="continuous">
        <origin xyz="-0.2 0.7 0" rpy="0.0 0.0 0.0"/>
        <parent link="right_rocker"/>
        <child link="wheel_back_right"/>
        <axis xyz="1 0 0"/>
        <limit effort="0" velocity="0"/>
    </joint>


    <joint name="arm_link_joint" type="revolute">
        <origin xyz="0 -0.5 0.4" rpy="0.0 0.0 0.0"/>
        <parent link="base_link"/>
        <child link="arm_link"/>
        <axis xyz="1 0 0"/>
        <limit lower="0" upper="0" effort="0" velocity="0"/>
    </joint>

   

    <joint name="arm2_link2_joint" type="revolute">
        <origin xyz="0 0 0.70" rpy="0.0 0.0 0.0"/>
        <parent link="arm_link"/>
        <child link="arm2_link2"/>
        <axis xyz="1 0 0"/>
        <limit lower="0" upper="0" effort="0" velocity="0"/>
    </joint>

<<<<<<< HEAD
=======
    <joint name="arm2_connector2_joint" type="revolute">
        <origin xyz="0 0.3 -0.1" rpy="0.0 0.0 0.0"/>
        <parent link="arm2_link2"/>
        <child link="arm2_connector2"/>
        <axis xyz="1 0 0"/>
        <limit lower="0" upper="0" effort="0" velocity="0"/>
    </joint>
>>>>>>> 056fd1fc542b84a082a617a9aa1b547c30798cec

    <joint name="arm3_link3_joint" type="revolute">
        <origin xyz="0 -0.55 -0.13" rpy="0.0 0.0 0.0"/>
        <parent link="arm2_link2"/>
        <child link="arm3_link3"/>
        <axis xyz="1 0 0"/>
        <limit lower="0" upper="0" effort="0" velocity="0"/>
    </joint>

    <joint name="grip_connector_joint" type="revolute">
        <origin xyz="0 -0.2 -0.3" rpy="0.0 0.0 0.0"/>
        <parent link="arm3_link3"/>
        <child link="grip_connector"/>
        <axis xyz="1 0 0"/>
        <limit lower="0" upper="0" effort="0" velocity="0"/>
    </joint>

    <joint name="left_grip_joint" type="revolute">
        <origin xyz="0.07 -0.05 -0.1" rpy="0.0 0.0 0.0"/>
        <parent link="grip_connector"/>
        <child link="left_grip"/>
        <axis xyz="1 0 0"/>
        <limit lower="0" upper="0" effort="0" velocity="0"/>
    </joint>

    <joint name="right_grip_joint" type="revolute">
        <origin xyz="-0.07 -0.05 -0.1" rpy="0.0 0.0 0.0"/>
        <parent link="grip_connector"/>
        <child link="right_grip"/>
        <axis xyz="1 0 0"/>
        <limit lower="0" upper="0" effort="0" velocity="0"/>
    </joint>

    <gazebo>
        <plugin name="gazebo_ros_control" filename="libgazebo_ros_control.so">
            <robotNamespace>/</robotNamespace>
        </plugin>
    </gazebo>

</robot>
