<?xml version="1.0"?>

<robot name="rover_model" 
    xmlns:xacro="http://www.ros.org/wiki/xacro">

    <material name="black">
        <color rgba="0 0 0 1"/>
    </material>
    <material name="green">
        <color rgba="${111/255} ${155/255} ${137/255} 1.0"/>
    </material>
    <material name="white">
        <color rgba="1 1 1 1"/>
    </material>
    <material name="purple">
        <color rgba="${78/255} ${88/255} ${188/255} 1.0"/>
    </material>
    <material name="brown">
        <color rgba="${112/255} ${51/255} ${10/255} 1.0"/>
    </material>
    <material name="grey">
        <color rgba="${203/255} ${200/255} ${191/255} 1.0"/>
    </material>

    <xacro:macro name="default_inertial" params="mass">
        <inertial>
            <mass value="${mass}" />
            <inertia ixx="1.0" ixy="0.0" ixz="0.0" iyy="1.0" iyz="0.0" izz="1.0" />
        </inertial>
    </xacro:macro>

    <link name="base_link">
        <visual>
            <geometry>
                <box size="0.7 1.4 0.4"/>
            </geometry>
            <origin rpy="0 0 0" xyz="0 0 0.2"/>
            <material name="brown"/>
        </visual>
        <collision>
            <geometry>
                <box size="0.7 1.4 0.4"/>
            </geometry>
            <origin rpy="0 0 0" xyz="0 0 0.2"/>
        </collision>
        <inertial>
            <mass value="30" />
            <inertia ixx="1.0" ixy="0.0" ixz="0.0" iyy="1.0" iyz="0.0" izz="1.0" />
        </inertial>
    </link>

    <link name="left_rocker">
        <visual>
            <geometry>
                <box size="0.2 1.4 0.2"/>
            </geometry>
            <origin rpy="0 0 0" xyz="0.1 0 0.1"/>
            <material name="grey"/>
        </visual>
        <collision>
            <geometry>
                <box size="0.2 1.4 0.2"/>
            </geometry>
            <origin rpy="0 0 0" xyz="0.1 0 0.1"/>
        </collision>
        <inertial>
            <mass value="1" />
            <inertia ixx="1.0" ixy="0.0" ixz="0.0" iyy="1.0" iyz="0.0" izz="1.0" />
        </inertial>
    </link>

    <joint name="left_rocker_joint" type="revolute">
        <parent link="base_link"/>
        <child link="left_rocker"/>
        <origin xyz="0.35 0.0 0.0" rpy="0.0 0.0 0.0"/>
        <axis xyz="1 0 0"/>
        <!-- <limit lower="-0.5235988" upper="0.5235988" effort="0.0" velocity="0.0"/> -->
        <limit lower="0" upper="0" effort="0.0" velocity="0.0"/>
    </joint>

    <transmission name="left_rocker_trans">
        <type>transmission_interface/SimpleTransmission</type>
        <joint name="left_rocker_joint">
            <hardwareInterface>hardware_interface/EffortJointInterface</hardwareInterface>
        </joint>
        <actuator name="left_rocker_motor">
            <mechanicalReduction>1</mechanicalReduction>
        </actuator>
    </transmission>

    <link name="right_rocker">
        <visual>
            <geometry>
                <box size="0.2 1.4 0.2"/>
            </geometry>
            <origin rpy="0 0 0" xyz="-0.1 0 0.1"/>
            <material name="grey"/>
        </visual>
        <collision>
            <geometry>
                <box size="0.2 1.4 0.2"/>
            </geometry>
            <origin rpy="0 0 0" xyz="-0.1 0 0.1"/>
        </collision>
        <inertial>
            <mass value="1" />
            <inertia ixx="1.0" ixy="0.0" ixz="0.0" iyy="1.0" iyz="0.0" izz="1.0" />
        </inertial>
    </link>

    <joint name="right_rocker_joint" type="revolute">
        <parent link="base_link"/>
        <child link="right_rocker"/>
        <origin xyz="-0.35 0.0 0.0" rpy="0.0 0.0 0.0"/>
        <axis xyz="1 0 0"/>
        <!-- <limit lower="-0.5235988" upper="0.5235988" effort="0" velocity="0"/> -->
        <limit lower="0" upper="0" effort="0" velocity="0"/>
    </joint>

    <transmission name="right_rocker_trans">
        <type>transmission_interface/SimpleTransmission</type>
        <joint name="right_rocker_joint">
            <hardwareInterface>hardware_interface/EffortJointInterface</hardwareInterface>
        </joint>
        <actuator name="right_rocker_motor">
            <mechanicalReduction>1</mechanicalReduction>
        </actuator>
    </transmission>

    <xacro:macro name="wheel" params="prefix suffix reflect_x reflect_y">

        <link name="wheel_${prefix}_${suffix}">
            <visual>
                <geometry>
                    <cylinder radius="0.15" length="0.2"/>
                </geometry>
                <origin rpy="0 1.570796 0" xyz="${reflect_x*0.1} 0 0"/>
                <material name="black"/>
            </visual>
            <collision>
                <geometry>
                    <cylinder radius="0.15" length="0.2"/>
                </geometry>
                <origin rpy="0 1.570796 0" xyz="${reflect_x*0.1} 0 0"/>
            </collision>
            <xacro:default_inertial mass="1"/>
        </link>

        <joint name="wheel_${prefix}_${suffix}_joint" type="continuous">
            <origin xyz="${reflect_x*0.2} ${reflect_y*(-0.7)} 0.0" rpy="0.0 0.0 0.0"/>
            <parent link="${suffix}_rocker"/>   
            <child link="wheel_${prefix}_${suffix}"/>
            <axis xyz="1 0 0"/>
            <!-- <limit lower="0" upper="0" effort="0" velocity="0"/> -->
        </joint>

        <gazebo reference="wheel_${prefix}_{suffix}_joint">
            <!-- <mu1 value="200.0"/>
            <mu2 value="100.0"/>
            <kp value="10000000.0" />
            <kd value="1.0" /> -->
            <mu1>0.2</mu1>
            <mu2>0.2</mu2>
            <material>Gazebo/Grey</material>
        </gazebo>

        <transmission name="wheel_${prefix}_${suffix}_tran">
            <type>transmission_interface/SimpleTransmission</type>
            <joint name="wheel_${prefix}_${suffix}_joint">
                <hardwareInterface>hardware_interface/VelocityJointInterface</hardwareInterface>
            </joint>
            <actuator name="wheel_${prefix}_${suffix}_motor">
                <mechanicalReduction>1</mechanicalReduction>
            </actuator>
        </transmission>

    </xacro:macro>

    <xacro:wheel prefix="front" suffix="left" reflect_x="1" reflect_y="1"/>
    <xacro:wheel prefix="front" suffix="right" reflect_x="-1" reflect_y="1"/>
    <xacro:wheel prefix="back" suffix="left" reflect_x="1" reflect_y="-1"/>
    <xacro:wheel prefix="back" suffix="right" reflect_x="-1" reflect_y="-1"/>

    <link name="arm_link">
        <visual>
            <geometry>
                <box size="0.1 0.1 1.0"/>
            </geometry>
            <origin rpy="0 0 0" xyz="0 0 0.2"/>
        </visual>
        <collision>
            <geometry>
                <box size="0.1 0.1 1.0"/>
            </geometry>
            <origin rpy="0 0 0" xyz="0 0 0.2"/>
        </collision>
        <inertial>
            <mass value="0.1" />
            <inertia ixx="1.0" ixy="0.0" ixz="0.0" iyy="1.0" iyz="0.0" izz="1.0" />
        </inertial>
    </link>

    <link name="arm_connector">
        <visual>
            <geometry>
                <cylinder radius="0.05" length="0.1"/>
            </geometry>
            <origin rpy="0 1.570796 0" xyz="0 0 0.05"/>
            <material name="white"/>
        </visual>
        <collision>
            <geometry>
                <cylinder radius="0.05" length="0.1"/>
            </geometry>
            <origin rpy="0 1.570796 0" xyz="0 0 0.05"/>
        </collision>
        <inertial>
            <mass value="0.1" />
            <inertia ixx="1.0" ixy="0.0" ixz="0.0" iyy="1.0" iyz="0.0" izz="1.0" />
        </inertial>
    </link>

    <link name="arm2_link2">
        <visual>
            <geometry>
                <cylinder radius="0.05" length="0.7"/>
            </geometry>
            <origin rpy="1.3 0 0" xyz="0 0 -0.03"/>
            <material name="green"/>
        </visual>
        <collision>
            <geometry>
                <cylinder radius="0.05" length="0.7"/>
            </geometry>
            <origin rpy="1.3 0 0" xyz="0 0 -0.03"/>
        </collision>
        <inertial>
            <mass value="0.1" />
            <inertia ixx="1.0" ixy="0.0" ixz="0.0" iyy="1.0" iyz="0.0" izz="1.0" />
        </inertial>
    </link>

    <link name="arm2_connector2">
        <visual>
            <geometry>
                <cylinder radius="0.05" length="0.1"/>
            </geometry>
            <origin rpy="0 1.570796 0" xyz="0 0 0"/>
            <material name="white"/>
        </visual>
        <collision>
            <geometry>
                <cylinder radius="0.05" length="0.1"/>
            </geometry>
            <origin rpy="0 1.570796 0" xyz="0 0 0"/>
        </collision>
        <inertial>
            <mass value="0.1" />
            <inertia ixx="1.0" ixy="0.0" ixz="0.0" iyy="1.0" iyz="0.0" izz="1.0" />
        </inertial>
    </link>

    <link name="arm3_link3">
        <visual>
            <geometry>
                <cylinder radius="0.05" length="0.4"/>
            </geometry>
            <origin rpy="0.5 0 0" xyz="0 0 0"/>
            <material name="green"/>
        </visual>
        <collision>
            <geometry>
                <cylinder radius="0.05" length="0.4"/>
            </geometry>
            <origin rpy="0.5 0 0" xyz="0 0 0"/>
        </collision>
        <inertial>
            <mass value="0.1" />
            <inertia ixx="1.0" ixy="0.0" ixz="0.0" iyy="1.0" iyz="0.0" izz="1.0" />
        </inertial>
    </link>

    <link name="grip_connector">
        <visual>
            <geometry>
                <cylinder radius="0.05" length="0.25"/>
            </geometry>
            <origin rpy="0 1.570796 0" xyz="0 0 0"/>
            <material name="purple"/>
        </visual>
        <collision>
            <geometry>
                <cylinder radius="0.05" length="0.25"/>
            </geometry>
            <origin rpy="0 1.570796 0" xyz="0 0 0"/>
        </collision>
        <inertial>
            <mass value="0.1" />
            <inertia ixx="1.0" ixy="0.0" ixz="0.0" iyy="1.0" iyz="0.0" izz="1.0" />
        </inertial>
    </link>

    <link name="left_grip">
        <visual>
            <geometry>
                <cylinder radius="0.03" length="0.25"/>
            </geometry>
            <origin rpy="0 0.2 0" xyz="0 0 0"/>
            <material name="black"/>
        </visual>
        <collision>
            <geometry>
                <cylinder radius="0.03" length="0.25"/>
            </geometry>
            <origin rpy="0 0.2 0" xyz="0 0 0"/>
        </collision>
        <inertial>
            <mass value="0.1" />
            <inertia ixx="1.0" ixy="0.0" ixz="0.0" iyy="1.0" iyz="0.0" izz="1.0" />
        </inertial>
    </link>

    <link name="right_grip">
        <visual>
            <geometry>
                <cylinder radius="0.03" length="0.25"/>
            </geometry>
            <origin rpy="0 -0.2 0" xyz="0 0 0"/>
            <material name="black"/>
        </visual>
        <collision>
            <geometry>
                <cylinder radius="0.03" length="0.25"/>
            </geometry>
            <origin rpy="0 -0.2 0" xyz="0 0 0"/>
        </collision>
        <inertial>
            <mass value="0.1" />
            <inertia ixx="1.0" ixy="0.0" ixz="0.0" iyy="1.0" iyz="0.0" izz="1.0" />
        </inertial>
    </link>

    <joint name="arm_link_joint" type="revolute">
        <origin xyz="0 0.45 0.4" rpy="0.0 0.0 0.0"/>
        <parent link="base_link"/>
        <child link="arm_link"/>
        <axis xyz="1 0 0"/>
        <limit lower="0" upper="0" effort="0" velocity="0"/>
    </joint>

    <joint name="arm_connector_joint" type="revolute">
        <origin xyz="0 0 0.6" rpy="0.0 0.0 0.0"/>
        <parent link="arm_link"/>
        <child link="arm_connector"/>
        <axis xyz="1 0 0"/>
        <limit lower="0" upper="0" effort="0" velocity="0"/>
    </joint>

    <joint name="arm2_link2_joint" type="revolute">
        <origin xyz="0 0.3 0" rpy="0.0 0.0 0.0"/>
        <parent link="arm_connector"/>
        <child link="arm2_link2"/>
        <axis xyz="1 0 0"/>
        <limit lower="0" upper="0" effort="0" velocity="0"/>
    </joint>

    <joint name="arm2_connector2_joint" type="revolute">
        <origin xyz="0 0.3 -0.1" rpy="0.0 0.0 0.0"/>
        <parent link="arm2_link2"/>
        <child link="arm2_connector2"/>
        <axis xyz="1 0 0"/>
        <limit lower="0" upper="0" effort="0" velocity="0"/>
    </joint>

    <joint name="arm3_link3_joint" type="revolute">
        <origin xyz="0 0.05 -0.15" rpy="0.0 0.0 0.0"/>
        <parent link="arm2_connector2"/>
        <child link="arm3_link3"/>
        <axis xyz="1 0 0"/>
        <limit lower="0" upper="0" effort="0" velocity="0"/>
    </joint>

    <joint name="grip_connector_joint" type="revolute">
        <origin xyz="0 0.1 -0.2" rpy="0.0 0.0 0.0"/>
        <parent link="arm3_link3"/>
        <child link="grip_connector"/>
        <axis xyz="1 0 0"/>
        <limit lower="0" upper="0" effort="0" velocity="0"/>
    </joint>

    <joint name="left_grip_joint" type="revolute">
        <origin xyz="0.07 0 -0.1" rpy="0.0 0.0 0.0"/>
        <parent link="grip_connector"/>
        <child link="left_grip"/>
        <axis xyz="1 0 0"/>
        <limit lower="0" upper="0" effort="0" velocity="0"/>
    </joint>

    <joint name="right_grip_joint" type="revolute">
        <origin xyz="-0.07 0 -0.1" rpy="0.0 0.0 0.0"/>
        <parent link="grip_connector"/>
        <child link="right_grip"/>
        <axis xyz="1 0 0"/>
        <limit lower="0" upper="0" effort="0" velocity="0"/>
    </joint>

    <transmission name="arm_link_trans">
        <type>transmission_interface/SimpleTransmission</type>
        <joint name="arm_link_joint">
            <hardwareInterface>hardware_interface/EffortJointInterface</hardwareInterface>
        </joint>
        <actuator name="arm_link_motor">
            <mechanicalReduction>1</mechanicalReduction>
        </actuator>
    </transmission>

    <transmission name="arm_connector_trans">
        <type>transmission_interface/SimpleTransmission</type>
        <joint name="arm_connector_joint">
            <hardwareInterface>hardware_interface/EffortJointInterface</hardwareInterface>
        </joint>
        <actuator name="arm_connector_motor">
            <mechanicalReduction>1</mechanicalReduction>
        </actuator>
    </transmission>

    <transmission name="arm2_link2_trans">
        <type>transmission_interface/SimpleTransmission</type>
        <joint name="arm2_link2_joint">
            <hardwareInterface>hardware_interface/EffortJointInterface</hardwareInterface>
        </joint>
        <actuator name="arm2_link2_motor">
            <mechanicalReduction>1</mechanicalReduction>
        </actuator>
    </transmission>

    <transmission name="arm2_connector2_trans">
        <type>transmission_interface/SimpleTransmission</type>
        <joint name="arm2_connector2_joint">
            <hardwareInterface>hardware_interface/EffortJointInterface</hardwareInterface>
        </joint>
        <actuator name="arm2_connector2_motor">
            <mechanicalReduction>1</mechanicalReduction>
        </actuator>
    </transmission>

    <transmission name="arm3_link3_trans">
        <type>transmission_interface/SimpleTransmission</type>
        <joint name="arm3_link3_joint">
            <hardwareInterface>hardware_interface/EffortJointInterface</hardwareInterface>
        </joint>
        <actuator name="arm3_link3_motor">
            <mechanicalReduction>1</mechanicalReduction>
        </actuator>
    </transmission>

    <transmission name="grip_connector_trans">
        <type>transmission_interface/SimpleTransmission</type>
        <joint name="grip_connector_joint">
            <hardwareInterface>hardware_interface/EffortJointInterface</hardwareInterface>
        </joint>
        <actuator name="grip_connector_motor">
            <mechanicalReduction>1</mechanicalReduction>
        </actuator>
    </transmission>

    <transmission name="left_grip_trans">
        <type>transmission_interface/SimpleTransmission</type>
        <joint name="left_grip_joint">
            <hardwareInterface>hardware_interface/EffortJointInterface</hardwareInterface>
        </joint>
        <actuator name="left_grip_motor">
            <mechanicalReduction>1</mechanicalReduction>
        </actuator>
    </transmission>

    <transmission name="right_grip_trans">
        <type>transmission_interface/SimpleTransmission</type>
        <joint name="right_grip_joint">
            <hardwareInterface>hardware_interface/EffortJointInterface</hardwareInterface>
        </joint>
        <actuator name="right_grip_motor">
            <mechanicalReduction>1</mechanicalReduction>
        </actuator>
    </transmission>

    <gazebo>
        <plugin name="gazebo_ros_control" filename="libgazebo_ros_control.so">
            <robotNamespace>/</robotNamespace>
        </plugin>
    </gazebo>


</robot>
