<?xml version="1.0" encoding="utf-8"?>
<!-- =================================================================================== -->
<!-- |    This document was autogenerated by xacro from testarm.xacro                  | -->
<!-- |    EDITING THIS FILE BY HAND IS NOT RECOMMENDED                                 | -->
<!-- =================================================================================== -->
<robot name="testarm" xmlns:xacro="http://www.ros.org/wiki/xacro">
  <material name="black">
    <color rgba="0.0 0.0 0.0 1.0"/>
  </material>
  <material name="orange">
    <color rgba="1.0 0.4 0.0 1.0"/>
  </material>
  <link name="base_link">
    <collision>
      <origin rpy="0 0 0" xyz="0.0 0.0 0.0"/>
      <geometry>
        <cylinder length="0.1" radius="0.5"/>
      </geometry>
    </collision>
    <visual>
      <origin rpy="0 0 0" xyz="0.0 0.0 0.0"/>
      <geometry>
        <cylinder length="0.1" radius="0.5"/>
      </geometry>
    </visual>
    <inertial>
      <origin rpy="0 0 0" xyz="0 0 0"/>
      <mass value="100"/>
      <inertia ixx="6.33333333333" ixy="0" ixz="0" iyy="6.33333333333" iyz="0" izz="25.0"/>
    </inertial>
  </link>
  <joint name="joint_base" type="revolute">
    <parent link="base_link"/>
    <child link="link0"/>
    <origin rpy="0 0 0" xyz="0.3 0 0.05"/>
    <axis xyz="0 0 1"/>
    <limit effort="300" lower="-1.78539816339" upper="1.78539816339" velocity="1.571"/>
  </joint>
  <link name="link0">
    <collision>
      <origin rpy="0 0 0" xyz="0 0 0.05"/>
      <geometry>
        <cylinder length="0.1" radius="0.1"/>
      </geometry>
    </collision>
    <visual>
      <origin rpy="0 0 0" xyz="0 0 0.05"/>
      <geometry>
        <cylinder length="0.1" radius="0.1"/>
      </geometry>
      <material name="orange"/>
    </visual>
    <inertial>
      <origin rpy="0 0 0" xyz="0 0 0.05"/>
      <mass value="1"/>
      <inertia ixx="0.00333333333333" ixy="0" ixz="0" iyy="0.00333333333333" iyz="0" izz="0.05"/>
    </inertial>
  </link>
  <joint name="joint0" type="revolute">
    <parent link="link0"/>
    <child link="link1"/>
    <origin rpy="0 0 0" xyz="0 0 0.1"/>
    <axis xyz="0 1 0"/>
    <limit effort="300" lower="-1.78539816339" upper="1.78539816339" velocity="1.571"/>
  </joint>
  <link name="link1">
    <collision>
      <origin rpy="0 0 0" xyz="0 0 0.3"/>
      <geometry>
        <box size="0.05 0.05 0.6"/>
      </geometry>
    </collision>
    <visual>
      <origin rpy="0 0 0" xyz="0 0 0.3"/>
      <geometry>
        <box size="0.05 0.05 0.6"/>
      </geometry>
      <material name="black"/>
    </visual>
    <inertial>
      <origin rpy="0 0 0" xyz="0 0 0.3"/>
      <mass value="1"/>
      <inertia ixx="0.03020832125" ixy="0.0" ixz="0.0" iyy="0.03020832125" iyz="0.0" izz="0.0004166665"/>
    </inertial>
  </link>
  <joint name="joint1" type="revolute">
    <parent link="link1"/>
    <child link="link2"/>
    <origin rpy="0 0 0" xyz="0 0 0.6"/>
    <axis xyz="0 1 0"/>
    <limit effort="300" lower="-1.78539816339" upper="1.78539816339" velocity="1.571"/>
  </joint>
  <link name="link2">
    <collision>
      <origin rpy="0 0 0" xyz="0 0 0.1"/>
      <geometry>
        <box size="0.05 0.05 0.2"/>
      </geometry>
    </collision>
    <visual>
      <origin rpy="0 0 0" xyz="0 0 0.1"/>
      <geometry>
        <box size="0.05 0.05 0.2"/>
      </geometry>
      <material name="orange"/>
    </visual>
    <inertial>
      <origin rpy="0 0 0" xyz="0 0 0.1"/>
      <mass value="1"/>
      <inertia ixx="0.00354166525" ixy="0.0" ixz="0.0" iyy="0.00354166525" iyz="0.0" izz="0.0004166665"/>
    </inertial>
  </link>
  <joint name="joint2" type="revolute">
    <parent link="link2"/>
    <child link="link3"/>
    <origin rpy="0 0 0" xyz="0 0 0.2"/>
    <axis xyz="0 0 1"/>
    <limit effort="300" lower="-1.78539816339" upper="1.78539816339" velocity="1.571"/>
  </joint>
  <link name="link3">
    <collision>
      <origin rpy="0 0 0" xyz="0 0 0.1"/>
      <geometry>
        <box size="0.05 0.05 0.2"/>
      </geometry>
    </collision>
    <visual>
      <origin rpy="0 0 0" xyz="0 0 0.1"/>
      <geometry>
        <box size="0.05 0.05 0.2"/>
      </geometry>
      <material name="black"/>
    </visual>
    <inertial>
      <origin rpy="0 0 0" xyz="0 0 0.1"/>
      <mass value="1"/>
      <inertia ixx="0.00354166525" ixy="0.0" ixz="0.0" iyy="0.00354166525" iyz="0.0" izz="0.0004166665"/>
    </inertial>
  </link>
  <joint name="joint3" type="revolute">
    <parent link="link3"/>
    <child link="link4"/>
    <origin rpy="0 0 0" xyz="0 0 0.2"/>
    <axis xyz="0 1 0"/>
    <limit effort="300" lower="-1.78539816339" upper="1.78539816339" velocity="1.571"/>
  </joint>
  <link name="link4">
    <collision>
      <origin rpy="0 0 0" xyz="0 0 0.025"/>
      <geometry>
        <box size="0.05 0.05 0.05"/>
      </geometry>
    </collision>
    <visual>
      <origin rpy="0 0 0" xyz="0 0 0.025"/>
      <geometry>
        <box size="0.05 0.05 0.05"/>
      </geometry>
      <material name="orange"/>
    </visual>
    <inertial>
      <origin rpy="0 0 0" xyz="0 0 0.025"/>
      <mass value="1"/>
      <inertia ixx="0.0004166665" ixy="0.0" ixz="0.0" iyy="0.0004166665" iyz="0.0" izz="0.0004166665"/>
    </inertial>
  </link>
  <joint name="joint4" type="revolute">
    <parent link="link4"/>
    <child link="link5"/>
    <origin rpy="0 0 0" xyz="0 0 0.05"/>
    <axis xyz="0 0 1"/>
    <limit effort="300" lower="-1.78539816339" upper="1.78539816339" velocity="1.571"/>
  </joint>
  <link name="link5">
    <collision>
      <origin rpy="0 0 0" xyz="0 0 0.025"/>
      <geometry>
        <box size="0.05 0.05 0.05"/>
      </geometry>
    </collision>
    <visual>
      <origin rpy="0 0 0" xyz="0 0 0.025"/>
      <geometry>
        <box size="0.05 0.05 0.05"/>
      </geometry>
      <material name="black"/>
    </visual>
    <inertial>
      <origin rpy="0 0 0" xyz="0 0 0.025"/>
      <mass value="1"/>
      <inertia ixx="0.0004166665" ixy="0.0" ixz="0.0" iyy="0.0004166665" iyz="0.0" izz="0.0004166665"/>
    </inertial>
  </link>
  <joint name="joint5" type="revolute">
    <parent link="link5"/>
    <child link="gripper_left"/>
    <origin rpy="0 0 0" xyz="0 0.01 0.05"/>
    <axis xyz="1 0 0"/>
    <limit effort="300" lower="-1.78539816339" upper="1.78539816339" velocity="1.571"/>
  </joint>
  <joint name="joint6" type="revolute">
    <parent link="link5"/>
    <child link="gripper_right"/>
    <origin rpy="0 0 0" xyz="0 -0.01 0.05"/>
    <axis xyz="1 0 0"/>
    <limit effort="300" lower="-1.78539816339" upper="1.78539816339" velocity="1.571"/>
  </joint>
  <link name="gripper_left">
    <collision>
      <origin rpy="0 0 0" xyz="0 0 0.035"/>
      <geometry>
        <cylinder length="0.07" radius="0.01"/>
      </geometry>
    </collision>
    <visual>
      <origin rpy="0 0 0" xyz="0 0 0.035"/>
      <geometry>
        <cylinder length="0.07" radius="0.01"/>
      </geometry>
      <material name="orange"/>
    </visual>
    <inertial>
      <origin rpy="0 0 0" xyz="0 0 0.035"/>
      <mass value="1"/>
      <inertia ixx="0.000433333333333" ixy="0" ixz="0" iyy="0.000433333333333" iyz="0" izz="0.005"/>
    </inertial>
  </link>
  <link name="gripper_right">
    <collision>
      <origin rpy="0 0 0" xyz="0 0 0.035"/>
      <geometry>
        <cylinder length="0.07" radius="0.01"/>
      </geometry>
    </collision>
    <visual>
      <origin rpy="0 0 0" xyz="0 0 0.035"/>
      <geometry>
        <cylinder length="0.07" radius="0.01"/>
      </geometry>
      <material name="orange"/>
    </visual>
    <inertial>
      <origin rpy="0 0 0" xyz="0 0 0.035"/>
      <mass value="1"/>
      <inertia ixx="0.000433333333333" ixy="0" ixz="0" iyy="0.000433333333333" iyz="0" izz="0.005"/>
    </inertial>
  </link>
  <!-- Transmission is important to link the joint and the controller -->
  <transmission name="joint_base_trans">
    <type>transmission_interface/SimpleTransmission</type>
    <joint name="joint_base">
      <hardwareInterface>hardware_interface/EffortJointInterface</hardwareInterface>
    </joint>
    <actuator name="joint_base_motor">
      <mechanicalReduction>1</mechanicalReduction>
    </actuator>
  </transmission>
  <transmission name="joint0_trans">
    <type>transmission_interface/SimpleTransmission</type>
    <joint name="joint0">
      <hardwareInterface>hardware_interface/EffortJointInterface</hardwareInterface>
    </joint>
    <actuator name="joint0_motor">
      <mechanicalReduction>1</mechanicalReduction>
    </actuator>
  </transmission>
  <transmission name="joint1_trans">
    <type>transmission_interface/SimpleTransmission</type>
    <joint name="joint1">
      <hardwareInterface>hardware_interface/EffortJointInterface</hardwareInterface>
    </joint>
    <actuator name="joint1_motor">
      <mechanicalReduction>1</mechanicalReduction>
    </actuator>
  </transmission>
  <transmission name="joint2_trans">
    <type>transmission_interface/SimpleTransmission</type>
    <joint name="joint2">
      <hardwareInterface>hardware_interface/EffortJointInterface</hardwareInterface>
    </joint>
    <actuator name="joint2_motor">
      <mechanicalReduction>1</mechanicalReduction>
    </actuator>
  </transmission>
  <transmission name="joint3_trans">
    <type>transmission_interface/SimpleTransmission</type>
    <joint name="joint3">
      <hardwareInterface>hardware_interface/EffortJointInterface</hardwareInterface>
    </joint>
    <actuator name="joint3_motor">
      <mechanicalReduction>1</mechanicalReduction>
    </actuator>
  </transmission>
  <transmission name="joint4_trans">
    <type>transmission_interface/SimpleTransmission</type>
    <joint name="joint4">
      <hardwareInterface>hardware_interface/EffortJointInterface</hardwareInterface>
    </joint>
    <actuator name="joint4_motor">
      <mechanicalReduction>1</mechanicalReduction>
    </actuator>
  </transmission>
  <transmission name="joint5_trans">
    <type>transmission_interface/SimpleTransmission</type>
    <joint name="joint5">
      <hardwareInterface>hardware_interface/EffortJointInterface</hardwareInterface>
    </joint>
    <actuator name="joint5_motor">
      <mechanicalReduction>1</mechanicalReduction>
    </actuator>
  </transmission>
  <transmission name="joint6_trans">
    <type>transmission_interface/SimpleTransmission</type>
    <joint name="joint6">
      <hardwareInterface>hardware_interface/EffortJointInterface</hardwareInterface>
    </joint>
    <actuator name="joint6_motor">
      <mechanicalReduction>1</mechanicalReduction>
    </actuator>
  </transmission>
  <gazebo>
    <plugin filename="libgazebo_ros_joint_state_publisher.so" name="joint_state_publisher">
      <jointName>
            joint_base, 
            joint0, 
            joint1, 
            joint2,
            joint3,
            joint4,
            joint5,
            joint6
         </jointName>
      <robotNameSpace>/</robotNameSpace>
      <updateRate>100</updateRate>
      <alwaysOn>true</alwaysOn>
    </plugin>
  </gazebo>
  <!-- <gazebo>
      <plugin name="gazebo_ros_control" filename="libgazebo_ros_control.so">
         <robotNamespace>/</robotNamespace>
         <robotSimType>gazebo_ros_control/DefaultRobotHWSim</robotSimType>
         <legacyModeNS>true</legacyModeNS>
      </plugin>
   </gazebo> -->
  <gazebo>
    <plugin filename="libgazebo_ros_control.so" name="gazebo_ros_control">
      <robotNamespace>/nimrod</robotNamespace>
    </plugin>
  </gazebo>
</robot>

